Traceback (most recent call last):
  File "/usr/lib/python3/dist-packages/colcon_parallel_executor/executor/parallel.py", line 75, in execute
    loop.run_until_complete(future)
  File "/usr/lib/python3.10/asyncio/base_events.py", line 636, in run_until_complete
    self.run_forever()
  File "/usr/lib/python3.10/asyncio/base_events.py", line 603, in run_forever
    self._run_once()
  File "/usr/lib/python3.10/asyncio/base_events.py", line 1871, in _run_once
    event_list = self._selector.select(timeout)
  File "/usr/lib/python3.10/selectors.py", line 469, in select
    fd_event_list = self._selector.poll(timeout, max_ev)
KeyboardInterrupt

During handling of the above exception, another exception occurred:

Traceback (most recent call last):
  File "/usr/lib/python3/dist-packages/colcon_core/executor/__init__.py", line 91, in __call__
    rc = await self.task(*args, **kwargs)
  File "/usr/lib/python3/dist-packages/colcon_core/task/__init__.py", line 93, in __call__
    return await task_method(*args, **kwargs)
  File "/usr/lib/python3/dist-packages/colcon_ros/task/ament_cmake/build.py", line 59, in build
    rc = await extension.build(
  File "/usr/lib/python3/dist-packages/colcon_cmake/task/cmake/build.py", line 110, in build
    if await has_target(args.build_base, 'install'):
  File "/usr/lib/python3/dist-packages/colcon_cmake/task/cmake/__init__.py", line 57, in has_target
    return target in await get_makefile_targets(path)
  File "/usr/lib/python3/dist-packages/colcon_cmake/task/cmake/__init__.py", line 77, in get_makefile_targets
    output = await check_output([
  File "/usr/lib/python3/dist-packages/colcon_core/subprocess.py", line 129, in check_output
    assert not rc, f'Expected {args} to pass: {stderr_data}'
AssertionError: Expected ['/home/robot/.local/bin/cmake', '--build', '/home/robot/ws_moveit2/build/moveit_setup_controllers', '--target', 'help'] to pass: Fatal Python error: init_import_site: Failed to import the site module
Python runtime state: initialized
Traceback (most recent call last):
  File "<frozen importlib._bootstrap_external>", line 153, in _path_is_mode_type
  File "<frozen importlib._bootstrap_external>", line 147, in _path_stat
FileNotFoundError: [Errno 2] No such file or directory: '/usr/lib/python3.10/collections/__init__.abi3.so'

During handling of the above exception, another exception occurred:

Traceback (most recent call last):
  File "/usr/lib/python3.10/site.py", line 636, in <module>
    main()
  File "/usr/lib/python3.10/site.py", line 623, in main
    known_paths = addsitepackages(known_paths)
  File "/usr/lib/python3.10/site.py", line 406, in addsitepackages
    addsitedir(sitedir, known_paths)
  File "/usr/lib/python3.10/site.py", line 232, in addsitedir
    addpackage(sitedir, name, known_paths)
  File "/usr/lib/python3.10/site.py", line 192, in addpackage
    exec(line)
  File "<string>", line 1, in <module>
  File "/usr/lib/python3.10/importlib/util.py", line 14, in <module>
    from contextlib import contextmanager
  File "/usr/lib/python3.10/contextlib.py", line 5, in <module>
    from collections import deque
  File "<frozen importlib._bootstrap>", line 1027, in _find_and_load
  File "<frozen importlib._bootstrap>", line 1002, in _find_and_load_unlocked
  File "<frozen importlib._bootstrap>", line 945, in _find_spec
  File "<frozen importlib._bootstrap_external>", line 1439, in find_spec
  File "<frozen importlib._bootstrap_external>", line 1411, in _get_spec
  File "<frozen importlib._bootstrap_external>", line 1563, in find_spec
  File "<frozen importlib._bootstrap_external>", line 161, in _path_isfile
  File "<frozen importlib._bootstrap_external>", line 153, in _path_is_mode_type
KeyboardInterrupt

